2023-03-29 17:29:23,799 INFO    MainThread:18861 [internal.py:wandb_internal():92] W&B internal server running at pid: 18861, started at: 2023-03-29 17:29:23.797580
2023-03-29 17:29:23,802 INFO    WriterThread:18861 [datastore.py:open_for_write():77] open: /zhome/e0/1/158047/mdpi_robotics/LibMTL/wandb/run-20230329_172921-2suo7l9f/run-2suo7l9f.wandb
2023-03-29 17:29:23,810 DEBUG   SenderThread:18861 [sender.py:send():235] send: header
2023-03-29 17:29:23,810 DEBUG   SenderThread:18861 [sender.py:send():235] send: run
2023-03-29 17:29:24,010 ERROR   SenderThread:18861 [internal_api.py:execute():144] 403 response executing GraphQL.
2023-03-29 17:29:24,011 ERROR   SenderThread:18861 [internal_api.py:execute():145] {"errors":[{"message":"permission denied","path":["upsertBucket"],"extensions":{"code":"PERMISSION_ERROR"}}],"data":{"upsertBucket":null}}
2023-03-29 17:29:24,805 INFO    HandlerThread:18861 [handler.py:finish():790] shutting down handler
2023-03-29 17:29:24,806 INFO    WriterThread:18861 [datastore.py:close():281] close: /zhome/e0/1/158047/mdpi_robotics/LibMTL/wandb/run-20230329_172921-2suo7l9f/run-2suo7l9f.wandb
2023-03-29 17:29:24,807 ERROR   MainThread:18861 [internal.py:wandb_internal():167] Thread SenderThread:
Traceback (most recent call last):
  File "/zhome/e0/1/158047/.local/lib/python3.8/site-packages/wandb/sdk/lib/retry.py", line 102, in __call__
    result = self._call_fn(*args, **kwargs)
  File "/zhome/e0/1/158047/.local/lib/python3.8/site-packages/wandb/sdk/internal/internal_api.py", line 147, in execute
    six.reraise(*sys.exc_info())
  File "/zhome/e0/1/158047/miniconda3/envs/libmtl/lib/python3.8/site-packages/six.py", line 719, in reraise
    raise value
  File "/zhome/e0/1/158047/.local/lib/python3.8/site-packages/wandb/sdk/internal/internal_api.py", line 141, in execute
    return self.client.execute(*args, **kwargs)
  File "/zhome/e0/1/158047/.local/lib/python3.8/site-packages/wandb/vendor/gql-0.2.0/wandb_gql/client.py", line 52, in execute
    result = self._get_result(document, *args, **kwargs)
  File "/zhome/e0/1/158047/.local/lib/python3.8/site-packages/wandb/vendor/gql-0.2.0/wandb_gql/client.py", line 60, in _get_result
    return self.transport.execute(document, *args, **kwargs)
  File "/zhome/e0/1/158047/.local/lib/python3.8/site-packages/wandb/vendor/gql-0.2.0/wandb_gql/transport/requests.py", line 39, in execute
    request.raise_for_status()
  File "/zhome/e0/1/158047/.local/lib/python3.8/site-packages/requests/models.py", line 960, in raise_for_status
    raise HTTPError(http_error_msg, response=self)
requests.exceptions.HTTPError: 403 Client Error: Forbidden for url: https://api.wandb.ai/graphql

During handling of the above exception, another exception occurred:

Traceback (most recent call last):
  File "/zhome/e0/1/158047/.local/lib/python3.8/site-packages/wandb/apis/normalize.py", line 24, in wrapper
    return func(*args, **kwargs)
  File "/zhome/e0/1/158047/.local/lib/python3.8/site-packages/wandb/sdk/internal/internal_api.py", line 1315, in upsert_run
    response = self.gql(mutation, variable_values=variable_values, **kwargs)
  File "/zhome/e0/1/158047/.local/lib/python3.8/site-packages/wandb/sdk/lib/retry.py", line 118, in __call__
    if not check_retry_fn(e):
  File "/zhome/e0/1/158047/.local/lib/python3.8/site-packages/wandb/util.py", line 873, in no_retry_auth
    raise CommError("Permission denied, ask the project owner to grant you access")
wandb.errors.CommError: Permission denied, ask the project owner to grant you access

During handling of the above exception, another exception occurred:

Traceback (most recent call last):
  File "/zhome/e0/1/158047/.local/lib/python3.8/site-packages/wandb/sdk/internal/internal_util.py", line 54, in run
    self._run()
  File "/zhome/e0/1/158047/.local/lib/python3.8/site-packages/wandb/sdk/internal/internal_util.py", line 105, in _run
    self._process(record)
  File "/zhome/e0/1/158047/.local/lib/python3.8/site-packages/wandb/sdk/internal/internal.py", line 312, in _process
    self._sm.send(record)
  File "/zhome/e0/1/158047/.local/lib/python3.8/site-packages/wandb/sdk/internal/sender.py", line 237, in send
    send_handler(record)
  File "/zhome/e0/1/158047/.local/lib/python3.8/site-packages/wandb/sdk/internal/sender.py", line 695, in send_run
    self._init_run(run, config_value_dict)
  File "/zhome/e0/1/158047/.local/lib/python3.8/site-packages/wandb/sdk/internal/sender.py", line 719, in _init_run
    server_run, inserted = self._api.upsert_run(
  File "/zhome/e0/1/158047/.local/lib/python3.8/site-packages/wandb/apis/normalize.py", line 62, in wrapper
    six.reraise(CommError, CommError(message, err), sys.exc_info()[2])
  File "/zhome/e0/1/158047/miniconda3/envs/libmtl/lib/python3.8/site-packages/six.py", line 718, in reraise
    raise value.with_traceback(tb)
  File "/zhome/e0/1/158047/.local/lib/python3.8/site-packages/wandb/apis/normalize.py", line 24, in wrapper
    return func(*args, **kwargs)
  File "/zhome/e0/1/158047/.local/lib/python3.8/site-packages/wandb/sdk/internal/internal_api.py", line 1315, in upsert_run
    response = self.gql(mutation, variable_values=variable_values, **kwargs)
  File "/zhome/e0/1/158047/.local/lib/python3.8/site-packages/wandb/sdk/lib/retry.py", line 118, in __call__
    if not check_retry_fn(e):
  File "/zhome/e0/1/158047/.local/lib/python3.8/site-packages/wandb/util.py", line 873, in no_retry_auth
    raise CommError("Permission denied, ask the project owner to grant you access")
wandb.errors.CommError: Permission denied, ask the project owner to grant you access
2023-03-29 17:29:27,163 INFO    MainThread:18861 [internal.py:handle_exit():82] Internal process exited
